Workbook

Sheet LEGGIMI
A1: Fonti sul mercato e sulla spesa in cybersecurity in UE e Regno Unito
A3: Scopo | B3: Censimento delle fonti pubblicate sulla dimensione del mercato e sulla spesa in cybersecurity per i 27 Stati membri, il Regno Unito e l'UE nel suo insieme. Il file serve a confrontare e ancorare un modello bottom-up della spesa cyber delle imprese basato sul fatturato Eurostat SBS. Non contiene una nuova stima.
A4: Data della ricerca | B4: 08/10/2026
A5: Contenuto | B5: 1215 righe in Dati, 406 fonti in Fonti_Metodologie, 158 ricerche registrate in Ricerche_senza_esito. I conteggi aggiornati per paese sono nel foglio Copertura_Paesi.
A6: Fogli | B6: Dati riporta un numero per riga. Fonti_Metodologie riporta una scheda per ID_Fonte. Copertura_Paesi calcola con formule la copertura di ciascuno dei 29 ambiti. Ricerche_senza_esito registra le ricerche che non hanno prodotto dati. Cambi riporta le medie annue BCE e i fattori di conversione delle unità.
A7: ID_Fonte | B7: Schema ENTE-PRODOTTO-ANNOEDIZIONE. Le pagine paese di un editore multi-paese portano il codice paese nel prodotto, per esempio MORDOR-CYBERDE-2025.
A8: Valore in Mln € | B8: Formula viva. Valore originale per il fattore dell'unità diviso per il cambio BCE medio dell'anno di riferimento. Vuota per le percentuali. Per gli anni senza media annua si usa l'ultima media disponibile, evidenziata in giallo nel foglio Cambi.
A10: Definizioni
A11: Lato della stima | B11: Domanda (end user) se il numero nasce da dati raccolti presso chi acquista o usa la sicurezza. Offerta (fornitori) se nasce dai ricavi di chi vende. Misto se la fonte dichiara di combinare i due lati per quel numero, oppure se esiste solo un testo generico dell'editore (in tal caso Trasparenza C). Non determinabile se non c'è alcun elemento per classificare. La classificazione segue la costruzione del numero, non il nome che gli dà la fonte.
A12: Base della classificazione | B12: Dichiarata dalla fonte, oppure Dedotta con motivazione in una frase. Le celle dedotte sono in arancio.
A13: Approccio di calcolo | B13: Bottom-up, Top-down, Survey riportata all'universo, Modello previsionale o econometrico, Ripreso da altra fonte, Non dichiarato.
A14: Oggetto della misura | B14: Mercato domestico (acquisti di clienti nel paese), Spesa o budget delle organizzazioni, Ricavi dell'industria nazionale (incluso export), Rapporto di spesa, Budget pubblico dedicato.
A15: Tipo di valore | B15: Totale aggregato, Media per organizzazione, Mediana per organizzazione, Quota percentuale, Variazione percentuale. I valori per organizzazione, come le mediane ENISA NIS Investments, non vanno mai moltiplicati per il numero di imprese.
A16: Trasparenza | B16: A metodologia specifica per quel dato con campione o universo, perimetro e passaggi. B metodologia specifica ma sintetica. C solo testo metodologico generico dell'editore. D nessuna metodologia reperibile.
A17: Natura | B17: Consuntivo, Stima dell'anno in corso, Previsione. Un anno per riga.
A19: Codice colori
A20: Dato da fonte | B20: Testo blu su sfondo azzurro
A21: Formula | B21: Testo nero
A22: Collegamento tra fogli | B22: Testo verde, formule che leggono un altro foglio
A23: Parametro modificabile | B23: Sfondo giallo
A24: Classificazione dedotta | B24: Sfondo arancio
A26: Limiti noti
A27: Accesso alle pagine | B27: L'ambiente di esecuzione bloccava l'apertura diretta delle pagine web. Ogni valore è stato letto nell'estratto testuale della pagina o del PDF indicato in URL, restituito da un motore di ricerca che indicizza il contenuto della pagina. Le righe lette così riportano nelle Note la dicitura «Letto da estratto indicizzato della pagina». Valori letti da grafici o tabelle complesse vanno ricontrollati sul documento prima dell'uso.
A28: Report a pagamento | B28: Per i report a pagamento sono stati usati solo comunicati stampa, sintesi ed estratti gratuiti. Il tipo di accesso è registrato per ogni riga.
A29: Perimetri | B29: Fonti con numeri simili misurano perimetri diversi. Prima di confrontare due righe controllare Oggetto della misura, Clienti inclusi, Personale interno incluso, Segmenti inclusi e Lato della stima.
A30: Editori di ricerche di mercato | B30: Le pagine paese di molti editori multi-paese riportano valori senza metodologia specifica e spesso incoerenti tra editori. Sono registrate per completezza con trasparenza C o D.
A31: Cambi | B31: Medie annue dei tassi di riferimento BCE in unità di valuta per 1 euro, lette nelle serie Bundesbank «Euro foreign exchange reference rates of the ECB» e nella tabella OeNB «ECB reference rates, period average». Per gli anni senza media annua disponibile si usa l'ultima media annua, con cella gialla.
A32: Verifica finale | B32: Sono state riaperte le fonti di 565 righe, cioè tutti i totali aggregati dell'ultimo anno disponibile per area, fonte e indicatore, un campione casuale del 20% delle altre righe e le righe aggiunte dopo il campionamento. Esiti 545 confermate, 8 corrette, 10 non ritrovate o non rileggibili, 2 rimosse perché fuori perimetro. L'esito è riportato nelle Note di ogni riga verificata. Le righe non ritrovate restano nel foglio con l'indicazione di ricontrollo.
A33: Esclusioni | B33: Le spese IT complessive per organizzazione pubblicate da ENISA NIS Investments sono escluse perché prive di componente cyber. Restano le quote della spesa di sicurezza sul budget IT.
A34: Budget pubblici | B34: Per i budget pubblici la natura Consuntivo indica lo stanziamento di un anno passato, non la spesa effettiva. Alcune dotazioni pluriennali sono registrate in un solo anno, di norma quello di chiusura, con il periodo nelle Note.
A35: Statista | B35: Le pagine paese di Statista Market Insights mostrano i valori oscurati senza abbonamento. I valori Statista presenti sono letti da pagine pubbliche di Statista o da terzi che li citano, con Accesso e Fonte primaria indicati.
A36: Aggregati geografici | B36: L'Europa degli editori include di norma Regno Unito, Svizzera e Norvegia. DACH include la Svizzera, i Paesi nordici includono Norvegia e Islanda, la CEE di alcuni analisti include paesi extra UE. Il perimetro è indicato nelle Note.
A37: Copertura_Paesi | B37: Minimo e massimo in Mln € sono calcolati sui soli totali aggregati senza scomposizione, con oggetto Mercato domestico o Spesa o budget delle organizzazioni, natura Consuntivo, nell'ultimo anno di consuntivo disponibile per quei totali. Mettono a confronto perimetri diversi e servono solo a mostrare la dispersione.

Sheet Dati
A1: ID_Dato | B1: ID_Fonte | C1: Codice area | D1: Paese o area | E1: Livello geografico | F1: Ente | G1: Tipo di ente | H1: Titolo ed edizione | I1: Data di pubblicazione | J1: URL | K1: Fonte primaria | L1: Indicatore originale | M1: Descrizione | N1: Oggetto della misura | O1: Tipo di valore | P1: Scomposizione | Q1: Voce | R1: Valore originale | S1: Unità originale | T1: Valuta originale | U1: Anno di riferimento | V1: Natura | W1: Crescita dichiarata | X1: Valore in Mln € | Y1: Clienti inclusi | Z1: Personale interno incluso | AA1: Segmenti inclusi | AB1: Lato della stima | AC1: Base della classificazione | AD1: Approccio di calcolo | AE1: Metodologia in sintesi | AF1: Evidenza | AG1: Trasparenza | AH1: Accesso | AI1: Verificato su fonte primaria | AJ1: Note | AK1: Data di consultazione
A2: 1 | B2: EC-CSA2-2026 | C2: EU27 | D2: Unione europea (UE27) | E2: UE | F2: Commissione europea | G2: Istituzione UE | H2: Proposta di regolamento Cybersecurity Act 2, COM(2026) 11, scheda finanziaria (documento del Consiglio 5611/26) | I2: 20/01/2026 | J2: https://data.consilium.europa.eu/doc/document/ST-5611-2026-INIT/en/pdf | L2: ENISA yearly average budget (projection 2028-2034) | M2: Bilancio annuo medio previsto di ENISA nel periodo 2028-2034 secondo la proposta di Cybersecurity Act 2. | N2: Budget pubblico dedicato | O2: Totale aggregato | P2: Nessuna | Q2: Totale | R2: 49 | S2: milioni | T2: EUR | U2: 2028 | V2: Previsione | X2: =IF(OR($S2="%",$R2=""),"",$R2*INDEX(Cambi!$J$2:$J$5,MATCH($S2,Cambi!$I$2:$I$5,0))/IF($T2="EUR",1,INDEX(Cambi!$D:$D,MATCH($T2&"|"&$U2,Cambi!$C:$C,0)))) -> 49 | Y2: PA | Z2: Non specificato | AA2: Non specificato | AB2: Non determinabile | AC2: Dedotta. Dotazione di bilancio pubblico, non stima di mercato. | AD2: Non dichiarato | AE2: Dotazione di bilancio programmata, nessuna stima statistica. | AF2: estimated at EUR 341 million for 7 years or yearly average budget of EUR 49 million (projection for 2028 to 2034). | AG2: B | AH2: Pubblico | AI2: Sì | AJ2: Letto da estratto indicizzato della pagina. Media annua 2028-2034 registrata sul primo anno del periodo. | AK2: 08/10/2026
A3: 2 | B3: EC-CSA2-2026 | C3: EU27 | D3: Unione europea (UE27) | E3: UE | F3: Commissione europea | G3: Istituzione UE | H3: Proposta di regolamento Cybersecurity Act 2, COM(2026) 11, scheda finanziaria (documento del Consiglio 5611/26) | I3: 20/01/2026 | J3: https://data.consilium.europa.eu/doc/document/ST-5611-2026-INIT/en/pdf | L3: Estimated budget of the EU Cybersecurity Agency (ENISA), 2028-2034 | M3: Bilancio stimato di ENISA per i sette anni 2028-2034 nella proposta di Cybersecurity Act 2, pari a 49 milioni annui in media. | N3: Budget pubblico dedicato | O3: Totale aggregato | P3: Nessuna | Q3: Totale | R3: 341 | S3: milioni | T3: EUR | U3: 2034 | V3: Previsione | X3: =IF(OR($S3="%",$R3=""),"",$R3*INDEX(Cambi!$J$2:$J$5,MATCH($S3,Cambi!$I$2:$I$5,0))/IF($T3="EUR",1,INDEX(Cambi!$D:$D,MATCH($T3&"|"&$U3,Cambi!$C:$C,0)))) -> 341 | Y3: PA | Z3: Non specificato | AA3: Non specificato | AB3: Non determinabile | AC3: Dedotta. Dotazione di bilancio pubblico, non stima di mercato. | AD3: Non dichiarato | AE3: Dotazione di bilancio programmata, nessuna stima statistica. | AF3: budget of the EU Cybersecurity Agency (ENISA) ... was estimated at EUR 341 million for 7 years or yearly average budget of EUR 49 million | AG3: B | AH3: Pubblico | AI3: Sì | AJ3: Letto da estratto indicizzato della pagina. Totale settennale registrato sull'anno di chiusura. Aumento dell'81,5% rispetto al bilancio 2025. | AK3: 08/10/2026
A4: 3 | B4: EC-CYBERSOLIDARITY-2023 | C4: EU27 | D4: Unione europea (UE27) | E4: UE | F4: Commissione europea | G4: Istituzione UE | H4: Comunicato stampa IP/23/2243, Cyber Solidarity Act | I4: 18/04/2023 | J4: https://ec.europa.eu/commission/presscorner/api/files/document/print/en/ip_23_2243/IP_23_2243_EN.pdf | L4: Total budget for all actions under the EU Cyber Solidarity Act | M4: Bilancio complessivo delle azioni del Cyber Solidarity Act, finanziato per circa due terzi dal programma Europa digitale. | N4: Budget pubblico dedicato | O4: Totale aggregato | P4: Nessuna | Q4: Totale | R4: 1.1 | S4: miliardi | T4: EUR | U4: 2027 | V4: Previsione | X4: =IF(OR($S4="%",$R4=""),"",$R4*INDEX(Cambi!$J$2:$J$5,MATCH($S4,Cambi!$I$2:$I$5,0))/IF($T4="EUR",1,INDEX(Cambi!$D:$D,MATCH($T4&"|"&$U4,Cambi!$C:$C,0)))) -> 1100 | Y4: Imprese e PA | Z4: Non specificato | AA4: Non specificato | AB4: Non determinabile | AC4: Dedotta. Dotazione di bilancio pubblico, non stima di mercato. | AD4: Non dichiarato | AE4: Dotazione di bilancio programmata, nessuna stima statistica. | AF4: total budget for all actions under the EU Cyber Solidarity Act is of EUR 1.1 billion, of which about 2/3 | AG4: B | AH4: Pubblico | AI4: Sì | AJ4: Letto da estratto indicizzato della pagina. Include contributi degli Stati membri. Periodo fino al 2027 dedotto dal quadro finanziario pluriennale. | AK4: 08/10/2026
A5: 4 | B5: EC-DEPBROCHURE-2019 | C5: EU27 | D5: Unione europea (UE27) | E5: UE | F5: Commissione europea | G5: Istituzione UE | H5: Digital Europe for a more competitive, autonomous and sustainable Europe, brochure | I5: 23/09/2019 | J5: https://digital-strategy.ec.europa.eu/en/library/digital-europe-more-competitive-autonomous-and-sustainable-europe-brochure | L5: Digital Europe programme budget 2021-2027, Cybersecurity | M5: Quota cybersecurity della dotazione proposta del programma Europa digitale 2021-2027 pari a 7,58 miliardi. | N5: Budget pubblico dedicato | O5: Totale aggregato | P5: Nessuna | Q5: Totale | R5: 1.6 | S5: miliardi | T5: EUR | U5: 2027 | V5: Previsione | X5: =IF(OR($S5="%",$R5=""),"",$R5*INDEX(Cambi!$J$2:$J$5,MATCH($S5,Cambi!$I$2:$I$5,0))/IF($T5="EUR",1,INDEX(Cambi!$D:$D,MATCH($T5&"|"&$U5,Cambi!$C:$C,0)))) -> 1600 | Y5: Imprese e PA | Z5: Non specificato | AA5: Non specificato | AB5: Non determinabile | AC5: Dedotta. Dotazione di bilancio pubblico, non stima di mercato. | AD5: Non dichiarato | AE5: Dotazione di bilancio programmata, nessuna stima statistica. | AF5: €7.58 billion for High Performance Computing (€2.2 billion) Artificial Intelligence (€2 billion) Cybersecurity (€1.6 billion) | AG5: B | AH5: Pubblico | AI5: Sì | AJ5: Letto da estratto indicizzato della pagina. Dotazione proposta 2021-2027, registrata sull'anno di chiusura del periodo. Verifica finale 08/10/2026, valore confermato sulla fonte. Dotazione proposta nel 2019 per il periodo 2021-2027 confermata. | AK5: 08/10/2026
A6: 5 | B6: EC-DEPCYBER-2026 | C6: EU27 | D6: Unione europea (UE27) | E6: UE | F6: Commissione europea | G6: Istituzione UE | H6: EU cybersecurity policies, pagina Shaping Europe's digital future | I6: 30/09/2026 | J6: https://digital-strategy.ec.europa.eu/en/policies/cybersecurity-policies | L6: Digital Europe Programme investment into cybersecurity capacity | M6: Dotazione del programma Europa digitale 2021-2027 per capacità e infrastrutture di cybersecurity per PA, imprese e cittadini. | N6: Budget pubblico dedicato | O6: Totale aggregato | P6: Nessuna | Q6: Totale | R6: 1.9 | S6: miliardi | T6: EUR | U6: 2027 | V6: Previsione | X6: =IF(OR($S6="%",$R6=""),"",$R6*INDEX(Cambi!$J$2:$J$5,MATCH($S6,Cambi!$I$2:$I$5,0))/IF($T6="EUR",1,INDEX(Cambi!$D:$D,MATCH($T6&"|"&$U6,Cambi!$C:$C,0)))) -> 1900 | Y6: Imprese e PA | Z6: Non specificato | AA6: Non specificato | AB6: Non determinabile | AC6: Dedotta. Dotazione di bilancio pubblico, non stima di mercato. | AD6: Non dichiarato | AE6: Dotazione di bilancio programmata, nessuna stima statistica. | AF6: plans to invest €1.9 billion into cybersecurity capacity and the wide deployment of cybersecurity infrastructures and tools across the EU | AG6: B | AH6: Pubblico | AI6: Sì | AJ6: Letto da estratto indicizzato della pagina. Dotazione pluriennale 2021-2027, registrata sull'anno di chiusura del periodo. Valore diverso da 1,6 miliardi della proposta 2019 e da 2 miliardi della proposta 2018. | AK6: 08/10/2026
A7: 6 | B7: EC-DEPNEWS-2025 | C7: EU27 | D7: Unione europea (UE27) | E7: UE | F7: Commissione europea | G7: Istituzione UE | H7: Digital Europe Programme fuels digital transformation and skills development across Europe | I7: 18/12/2025 | J7: https://digital-strategy.ec.europa.eu/en/news/digital-europe-programme-fuels-digital-transformation-and-skills-development-across-europe | L7: DIGITAL funding for Security Operations Centres (Cyber Hubs) 2021-2024 | M7: Fondi del programma Europa digitale destinati tra 2021 e 2024 alla creazione e gestione di centri operativi di sicurezza (Cyber Hubs). | N7: Budget pubblico dedicato | O7: Totale aggregato | P7: Segmento di offerta | Q7: Centri operativi di sicurezza (SOC) | R7: 194 | S7: milioni | T7: EUR | U7: 2024 | V7: Consuntivo | X7: =IF(OR($S7="%",$R7=""),"",$R7*INDEX(Cambi!$J$2:$J$5,MATCH($S7,Cambi!$I$2:$I$5,0))/IF($T7="EUR",1,INDEX(Cambi!$D:$D,MATCH($T7&"|"&$U7,Cambi!$C:$C,0)))) -> 194 | Y7: Imprese e PA | Z7: Non specificato | AA7: Non specificato | AB7: Non determinabile | AC7: Dedotta. Dotazione di bilancio pubblico, non stima di mercato. | AD7: Non dichiarato | AE7: Dotazione di bilancio programmata, nessuna stima statistica. | AF7: Between 2021 and 2024 over €194 million was dedicated towards the creation and operation of Security Operations Centres | AG7: B | AH7: Pubblico | AI7: Sì | AJ7: Letto da estratto indicizzato della pagina. Cumulato 2021-2024, pubblicato come oltre 194 milioni. | AK7: 08/10/2026
A8: 7 | B8: EC-DIGITALDECADE-2024 | C8: EU27 | D8: Unione europea (UE27) | E8: UE | F8: Commissione europea | G8: Istituzione UE | H8: State of the Digital Decade 2024, COM(2024) 260 (copia IPEX) | I8: 02/07/2024 | J8: https://secure.ipex.eu/IPEXL-WEB/download/file/082d29089070f71e019072c2e24e0036 | L8: National roadmaps measures addressing cybersecurity, public budget | M8: Bilancio pubblico delle misure delle prime roadmap nazionali del Decennio digitale riferite all'obiettivo cybersecurity. | N8: Budget pubblico dedicato | O8: Totale aggregato | P8: Nessuna | Q8: Totale | R8: 5.9 | S8: miliardi | T8: EUR | U8: 2024 | V8: Previsione | X8: =IF(OR($S8="%",$R8=""),"",$R8*INDEX(Cambi!$J$2:$J$5,MATCH($S8,Cambi!$I$2:$I$5,0))/IF($T8="EUR",1,INDEX(Cambi!$D:$D,MATCH($T8&"|"&$U8,Cambi!$C:$C,0)))) -> 5900 | Y8: Imprese e PA | Z8: Non specificato | AA8: Non specificato | AB8: Non determinabile | AC8: Dedotta. Dotazione di bilancio pubblico, non stima di mercato. | AD8: Bottom-up | AE8: Somma del bilancio pubblico delle misure delle roadmap nazionali riferite all'obiettivo generale cybersecurity. | AF8: they still encompass 414 measures addressing competitiveness (public budget EUR 56.8 billion), technological leadership (EUR 22.3 billion), and cybersecurity (EUR 5.9 billion). | AG8: B | AH8: Pubblico | AI8: Sì | AJ8: Letto da estratto indicizzato della pagina. Periodo di spesa non specificato, registrato sull'anno della relazione. Diverso dal valore 2025 (0,8 miliardi solo per misure esclusivamente cyber) per perimetro delle misure. | AK8: 08/10/2026
A9: 8 | B9: EC-DIGITALDECADE-2025 | C9: EU27 | D9: Unione europea (UE27) | E9: UE | F9: Commissione europea | G9: Istituzione UE | H9: State of the Digital Decade 2025, allegato COM(2025) 290 | I9: 16/06/2025 | J9: https://www.europarl.europa.eu/RegData/docs_autres_institutions/commission_europeenne/com/2025/0290/COM_COM(2025)0290(ANN)_EN.pdf | L9: National Roadmaps measures dedicated exclusively to cybersecurity, total budget | M9: Bilancio complessivo delle misure delle roadmap nazionali del Decennio digitale dedicate esclusivamente alla cybersecurity. | N9: Budget pubblico dedicato | O9: Totale aggregato | P9: Nessuna | Q9: Totale | R9: 0.8 | S9: miliardi | T9: EUR | U9: 2025 | V9: Previsione | X9: =IF(OR($S9="%",$R9=""),"",$R9*INDEX(Cambi!$J$2:$J$5,MATCH($S9,Cambi!$I$2:$I$5,0))/IF($T9="EUR",1,INDEX(Cambi!$D:$D,MATCH($T9&"|"&$U9,Cambi!$C:$C,0)))) -> 800 | Y9: Imprese e PA | Z9: Non specificato | AA9: Non specificato | AB9: Non determinabile | AC9: Dedotta. Dotazione di bilancio pubblico, non stima di mercato. | AD9: Non dichiarato | AE9: Somma dei bilanci delle misure cyber dichiarate dagli Stati membri nelle roadmap nazionali del Decennio digitale. | AF9: Almost half of these measures are dedicated exclusively to cybersecurity, with a total budget of EUR 0.8 billion. | AG9: B | AH9: Pubblico | AI9: Sì | AJ9: Letto da estratto indicizzato della pagina. Le altre misure a portata più ampia valgono 6 miliardi. Periodo di spesa non specificato, registrato sull'anno della relazione. | AK9: 08/10/2026
A10: 9 | B10: EC-HEWP-2025 | C10: EU27 | D10: Unione europea (UE27) | E10: UE | F10: Commissione europea | G10: Istituzione UE | H10: Horizon Europe Work Programme 2025, 6. Civil Security for Society | I10: 2025 | J10: https://ec.europa.eu/info/funding-tenders/opportunities/docs/2021-2027/horizon/wp-call/2025/wp-6-civil-security-for-society_horizon-2025_en.pdf | L10: Indirectly managed action by the ECCC, Increased Cybersecurity call, indicative budget | M10: Bilancio indicativo 2025 del bando Horizon Europe Increased Cybersecurity gestito dall'ECCC. | N10: Budget pubblico dedicato | O10: Totale aggregato | P10: Segmento di offerta | Q10: Ricerca e innovazione (Horizon Europe) | R10: 90.55 | S10: milioni | T10: EUR | U10: 2025 | V10: Previsione | X10: =IF(OR($S10="%",$R10=""),"",$R10*INDEX(Cambi!$J$2:$J$5,MATCH($S10,Cambi!$I$2:$I$5,0))/IF($T10="EUR",1,INDEX(Cambi!$D:$D,MATCH($T10&"|"&$U10,Cambi!$C:$C,0)))) -> 90.55 | Y10: Imprese e PA | Z10: Non specificato | AA10: Non specificato | AB10: Non determinabile | AC10: Dedotta. Dotazione di bilancio pubblico, non stima di mercato. | AD10: Non dichiarato | AE10: Dotazione di bilancio programmata, nessuna stima statistica. | AF10: Indicative budget: EUR 90.55 million from the 2025 budget APPENDIX - Indirectly managed action by the ECCC | AG10: B | AH10: Pubblico | AI10: Sì | AJ10: Letto da estratto indicizzato della pagina. Solo il bando cyber ECCC del 2025, non l'intero impegno Horizon Europe sulla cybersecurity. | AK10: 08/10/2026
A11: 10 | B11: EC-IANIS2-2020 | C11: EU27 | D11: Unione europea (UE27) | E11: UE | F11: Commissione europea | G11: Istituzione UE | H11: SWD(2020) 345 final, Impact assessment report revisione direttiva NIS (allegati) | I11: 16/12/2020 | J11: https://www.eerstekamer.nl/bijlage/20210114/swd_2020_345_impact_assessment_7/document3/f=/vlfghch5jfhz.pdf | K11: Gartner, previsioni 2012-2020 sulla quota di spesa di sicurezza ICT e dati settoriali, citate dalla Commissione | L11: Average ICT security spending of the total turnover per sector | M11: Ipotesi della Commissione sulla spesa media di sicurezza ICT dei settori NIS nel 2020 in rapporto al fatturato. | N11: Rapporto di spesa | O11: Quota percentuale | P11: Nessuna | Q11: Totale | R11: 0.52 | S11: % | U11: 2020 | V11: Stima dell'anno in corso | X11: =IF(OR($S11="%",$R11=""),"",$R11*INDEX(Cambi!$J$2:$J$5,MATCH($S11,Cambi!$I$2:$I$5,0))/IF($T11="EUR",1,INDEX(Cambi!$D:$D,MATCH($T11&"|"&$U11,Cambi!$C:$C,0)))) | Y11: Imprese e PA | Z11: Non specificato | AA11: Spesa di sicurezza ICT (perimetro Gartner) | AB11: Non determinabile | AC11: Dedotta. Ipotesi della Commissione costruita su rapporti Gartner globali, non su dati di acquirenti o fornitori UE. | AD11: Modello previsionale o econometrico | AE11: Ipotesi di lavoro della valutazione d'impatto basata su previsioni Gartner 2012-2020 della spesa di sicurezza ICT in rapporto alla spesa ICT e al fatturato, aggiustabile di più o meno 3 punti per settore, applicata al fatturato dei settori NIS. | AF11: the average ICT security spending of the total turnover per sector in 2020 is estimated to approx. 0.52%. | AG11: B | AH11: Pubblico | AI11: Sì | AJ11: Letto da estratto indicizzato della pagina. Prodotto di 9,14% di spesa ICT e 5,69% di spesa ICT sul fatturato. Rapporto direttamente confrontabile con modelli basati sul fatturato SBS. Verifica finale 08/10/2026, valore confermato sulla fonte. Valore e anno coincidono nella valutazione d'impatto NIS2. | AK11: 08/10/2026
A12: 11 | B12: EC-IANIS2-2020 | C12: EU27 | D12: Unione europea (UE27) | E12: UE | F12: Commissione europea | G12: Istituzione UE | H12: SWD(2020) 345 final, Impact assessment report revisione direttiva NIS (allegati) | I12: 16/12/2020 | J12: https://www.eerstekamer.nl/bijlage/20210114/swd_2020_345_impact_assessment_7/document3/f=/vlfghch5jfhz.pdf | K12: Gartner, previsioni 2012-2020 sulla quota di spesa di sicurezza ICT e dati settoriali, citate dalla Commissione | L12: Average ICT security spending per sector, % of ICT spending | M12: Ipotesi della Commissione sulla spesa media di sicurezza ICT dei settori NIS nel 2020 in rapporto alla spesa ICT. | N12: Rapporto di spesa | O12: Quota percentuale | P12: Nessuna | Q12: Totale | R12: 9.14 | S12: % | U12: 2020 | V12: Stima dell'anno in corso | X12: =IF(OR($S12="%",$R12=""),"",$R12*INDEX(Cambi!$J$2:$J$5,MATCH($S12,Cambi!$I$2:$I$5,0))/IF($T12="EUR",1,INDEX(Cambi!$D:$D,MATCH($T12&"|"&$U12,Cambi!$C:$C,0)))) | Y12: Imprese e PA | Z12: Non specificato | AA12: Spesa di sicurezza ICT (perimetro Gartner) | AB12: Non determinabile | AC12: Dedotta. Ipotesi della Commissione costruita su rapporti Gartner globali, non su dati di acquirenti o fornitori UE. | AD12: Modello previsionale o econometrico | AE12: Ipotesi di lavoro della valutazione d'impatto basata su previsioni Gartner 2012-2020 della spesa di sicurezza ICT in rapporto alla spesa ICT e al fatturato, aggiustabile di più o meno 3 punti per settore, applicata al fatturato dei settori NIS. | AF12: the average ICT security spending per sector in 2020 is of approx. 9.14% of the ICT spending. | AG12: B | AH12: Pubblico | AI12: Sì | AJ12: Letto da estratto indicizzato della pagina. Ipotesi derivata da dati Gartner globali, non da misura UE. Documento ufficiale ospitato dal Senato dei Paesi Bassi. | AK12: 08/10/2026
A13: 12 | B13: EC-IANIS2-2020 | C13: EU27 | D13: Unione europea (UE27) | E13: UE | F13: Commissione europea | G13: Istituzione UE | H13: SWD(2020) 345 final, Impact assessment report revisione direttiva NIS (allegati) | I13: 16/12/2020 | J13: https://www.eerstekamer.nl/bijlage/20210114/swd_2020_345_impact_assessment_5/document3/f=/vlfghbk7smnk.pdf | K13: Gartner, previsioni 2012-2020 sulla quota di spesa di sicurezza ICT e dati settoriali, citate dalla Commissione | L13: Average increase in ICT security spending for sectors currently under NIS scope | M13: Aumento medio previsto della spesa di sicurezza ICT per i settori già coperti dalla direttiva NIS nei tre o quattro anni successivi. | N13: Spesa o budget delle organizzazioni | O13: Variazione percentuale | P13: Settore | Q13: Settori già NIS | R13: 12 | S13: % | U13: 2025 | V13: Previsione | X13: =IF(OR($S13="%",$R13=""),"",$R13*INDEX(Cambi!$J$2:$J$5,MATCH($S13,Cambi!$I$2:$I$5,0))/IF($T13="EUR",1,INDEX(Cambi!$D:$D,MATCH($T13&"|"&$U13,Cambi!$C:$C,0)))) | Y13: Imprese e PA | Z13: Non specificato | AA13: Spesa di sicurezza ICT (perimetro Gartner) | AB13: Non determinabile | AC13: Dedotta. Ipotesi della Commissione costruita su rapporti Gartner globali, non su dati di acquirenti o fornitori UE. | AD13: Modello previsionale o econometrico | AE13: Ipotesi di lavoro della valutazione d'impatto basata su previsioni Gartner 2012-2020 della spesa di sicurezza ICT in rapporto alla spesa ICT e al fatturato, aggiustabile di più o meno 3 punti per settore, applicata al fatturato dei settori NIS. | AF13: average 12% increase in ICT security spending is estimated for the sectors/services currently under the scope of the NIS Directive | AG13: B | AH13: Pubblico | AI13: Sì | AJ13: Letto da estratto indicizzato della pagina. Variazione cumulata sull'orizzonte, non annua. | AK13: 08/10/2026
A14: 13 | B14: EC-IANIS2-2020 | C14: EU27 | D14: Unione europea (UE27) | E14: UE | F14: Commissione europea | G14: Istituzione UE | H14: SWD(2020) 345 final, Impact assessment report revisione direttiva NIS (allegati) | I14: 16/12/2020 | J14: https://www.eerstekamer.nl/bijlage/20210114/swd_2020_345_impact_assessment_5/document3/f=/vlfghbk7smnk.pdf | K14: Gartner, previsioni 2012-2020 sulla quota di spesa di sicurezza ICT e dati settoriali, citate dalla Commissione | L14: Average increase in ICT security spending for the new sectors/services added to the NIS scope | M14: Aumento medio previsto della spesa di sicurezza ICT per i nuovi settori NIS2 nei tre o quattro anni successivi. | N14: Spesa o budget delle organizzazioni | O14: Variazione percentuale | P14: Settore | Q14: Nuovi settori NIS2 | R14: 22 | S14: % | U14: 2025 | V14: Previsione | X14: =IF(OR($S14="%",$R14=""),"",$R14*INDEX(Cambi!$J$2:$J$5,MATCH($S14,Cambi!$I$2:$I$5,0))/IF($T14="EUR",1,INDEX(Cambi!$D:$D,MATCH($T14&"|"&$U14,Cambi!$C:$C,0)))) | Y14: Imprese e PA | Z14: Non specificato | AA14: Spesa di sicurezza ICT (perimetro Gartner) | AB14: Non determinabile | AC14: Dedotta. Ipotesi della Commissione costruita su rapporti Gartner globali, non su dati di acquirenti o fornitori UE. | AD14: Modello previsionale o econometrico | AE14: Ipotesi di lavoro della valutazione d'impatto basata su previsioni Gartner 2012-2020 della spesa di sicurezza ICT in rapporto alla spesa ICT e al fatturato, aggiustabile di più o meno 3 punti per settore, applicata al fatturato dei settori NIS. | AF14: Average 22% increase in ICT security spending for the new sectors/services added to the NIS scope in the next 3-4 years. | AG14: B | AH14: Pubblico | AI14: Sì | AJ14: Letto da estratto indicizzato della pagina. Variazione cumulata sull'orizzonte, non annua. | AK14: 08/10/2026
A15: 14 | B15: EC-IANIS2-2020 | C15: EU27 | D15: Unione europea (UE27) | E15: UE | F15: Commissione europea | G15: Istituzione UE | H15: SWD(2020) 345 final, Impact assessment report revisione direttiva NIS (allegati) | I15: 16/12/2020 | J15: https://www.eerstekamer.nl/bijlage/20210114/swd_2020_345_impact_assessment_7/document3/f=/vlfghch5jfhz.pdf | K15: Gartner, previsioni 2012-2020 sulla quota di spesa di sicurezza ICT e dati settoriali, citate dalla Commissione | L15: ICT security spending in average per sector, % of ICT spending, after revised NIS Directive (current sectors) | M15: Quota prevista della spesa di sicurezza ICT sulla spesa ICT per i settori già NIS, tre o quattro anni dopo l'entrata in vigore della NIS2. | N15: Rapporto di spesa | O15: Quota percentuale | P15: Nessuna | Q15: Totale | R15: 11 | S15: % | U15: 2025 | V15: Previsione | X15: =IF(OR($S15="%",$R15=""),"",$R15*INDEX(Cambi!$J$2:$J$5,MATCH($S15,Cambi!$I$2:$I$5,0))/IF($T15="EUR",1,INDEX(Cambi!$D:$D,MATCH($T15&"|"&$U15,Cambi!$C:$C,0)))) | Y15: Imprese e PA | Z15: Non specificato | AA15: Spesa di sicurezza ICT (perimetro Gartner) | AB15: Non determinabile | AC15: Dedotta. Ipotesi della Commissione costruita su rapporti Gartner globali, non su dati di acquirenti o fornitori UE. | AD15: Modello previsionale o econometrico | AE15: Ipotesi di lavoro della valutazione d'impatto basata su previsioni Gartner 2012-2020 della spesa di sicurezza ICT in rapporto alla spesa ICT e al fatturato, aggiustabile di più o meno 3 punti per settore, applicata al fatturato dei settori NIS. | AF15: ICT security spending in average per sector reaching about 11% of the ICT spending and 0.63% of the total turnover in three to four years | AG15: B | AH15: Pubblico | AI15: Sì | AJ15: Letto da estratto indicizzato della pagina. Orizzonte dichiarato tre o quattro anni dall'entrata in vigore, anno 2025 dedotto e approssimativo. | AK15: 08/10/2026
A16: 15 | B16: EC-IANIS2-2020 | C16: EU27 | D16: Unione europea (UE27) | E16: UE | F16: Commissione europea | G16: Istituzione UE | H16: SWD(2020) 345 final, Impact assessment report revisione direttiva NIS (allegati) | I16: 16/12/2020 | J16: https://www.eerstekamer.nl/bijlage/20210114/swd_2020_345_impact_assessment_7/document3/f=/vlfghch5jfhz.pdf | K16: Gartner, previsioni 2012-2020 sulla quota di spesa di sicurezza ICT e dati settoriali, citate dalla Commissione | L16: ICT security spending in average per sector, % of total turnover, after revised NIS Directive (current sectors) | M16: Quota prevista della spesa di sicurezza ICT sul fatturato per i settori già NIS, tre o quattro anni dopo l'entrata in vigore della NIS2. | N16: Rapporto di spesa | O16: Quota percentuale | P16: Nessuna | Q16: Totale | R16: 0.63 | S16: % | U16: 2025 | V16: Previsione | X16: =IF(OR($S16="%",$R16=""),"",$R16*INDEX(Cambi!$J$2:$J$5,MATCH($S16,Cambi!$I$2:$I$5,0))/IF($T16="EUR",1,INDEX(Cambi!$D:$D,MATCH($T16&"|"&$U16,Cambi!$C:$C,0)))) | Y16: Imprese e PA | Z16: Non specificato | AA16: Spesa di sicurezza ICT (perimetro Gartner) | AB16: Non determinabile | AC16: Dedotta. Ipotesi della Commissione costruita su rapporti Gartner globali, non su dati di acquirenti o fornitori UE. | AD16: Modello previsionale o econometrico | AE16: Ipotesi di lavoro della valutazione d'impatto basata su previsioni Gartner 2012-2020 della spesa di sicurezza ICT in rapporto alla spesa ICT e al fatturato, aggiustabile di più o meno 3 punti per settore, applicata al fatturato dei settori NIS. | AF16: ICT security spending in average per sector reaching about 11% of the ICT spending and 0.63% of the total turnover in three to four years | AG16: B | AH16: Pubblico | AI16: Sì | AJ16: Letto da estratto indicizzato della pagina. Anno 2025 dedotto e approssimativo. | AK16: 08/10/2026
A17: 16 | B17: EC-IANIS2-2020 | C17: EU27 | D17: Unione europea (UE27) | E17: UE | F17: Commissione europea | G17: Istituzione UE | H17: SWD(2020) 345 final, Impact assessment report revisione direttiva NIS (allegati) | I17: 16/12/2020 | J17: https://www.eerstekamer.nl/bijlage/20210114/swd_2020_345_impact_assessment_7/document3/f=/vlfghch5jfhz.pdf | K17: Gartner, previsioni 2012-2020 sulla quota di spesa di sicurezza ICT e dati settoriali, citate dalla Commissione | L17: ICT security spending in average per sector, new sectors, % of ICT spending | M17: Quota prevista della spesa di sicurezza ICT sulla spesa ICT per i nuovi settori NIS2, tre o quattro anni dopo l'entrata in vigore. | N17: Rapporto di spesa | O17: Quota percentuale | P17: Settore | Q17: Nuovi settori NIS2 | R17: 11.4 | S17: % | U17: 2025 | V17: Previsione | X17: =IF(OR($S17="%",$R17=""),"",$R17*INDEX(Cambi!$J$2:$J$5,MATCH($S17,Cambi!$I$2:$I$5,0))/IF($T17="EUR",1,INDEX(Cambi!$D:$D,MATCH($T17&"|"&$U17,Cambi!$C:$C,0)))) | Y17: Imprese e PA | Z17: Non specificato | AA17: Spesa di sicurezza ICT (perimetro Gartner) | AB17: Non determinabile | AC17: Dedotta. Ipotesi della Commissione costruita su rapporti Gartner globali, non su dati di acquirenti o fornitori UE. | AD17: Modello previsionale o econometrico | AE17: Ipotesi di lavoro della valutazione d'impatto basata su previsioni Gartner 2012-2020 della spesa di sicurezza ICT in rapporto alla spesa ICT e al fatturato, aggiustabile di più o meno 3 punti per settore, applicata al fatturato dei settori NIS. | AF17: For the new sectors, this would translate into ICT security spending in average per sector reaching about 11.4% of the ICT spending and 0.65% | AG17: B | AH17: Pubblico | AI17: Sì | AJ17: Letto da estratto indicizzato della pagina. Anno 2025 dedotto e approssimativo. Verifica finale 08/10/2026, valore confermato sulla fonte. Quota prevista a tre o quattro anni dalla direttiva rivista, coerente con la riga. | AK17: 08/10/2026
A18: 17 | B18: EC-IANIS2-2020 | C18: EU27 | D18: Unione europea (UE27) | E18: UE | F18: Commissione europea | G18: Istituzione UE | H18: SWD(2020) 345 final, Impact assessment report revisione direttiva NIS (allegati) | I18: 16/12/2020 | J18: https://www.eerstekamer.nl/bijlage/20210114/swd_2020_345_impact_assessment_7/document3/f=/vlfghch5jfhz.pdf | K18: Gartner, previsioni 2012-2020 sulla quota di spesa di sicurezza ICT e dati settoriali, citate dalla Commissione | L18: ICT security spending in average per sector, new sectors, % of total turnover | M18: Quota prevista della spesa di sicurezza ICT sul fatturato per i nuovi settori NIS2, tre o quattro anni dopo l'entrata in vigore. | N18: Rapporto di spesa | O18: Quota percentuale | P18: Settore | Q18: Nuovi settori NIS2 | R18: 0.65 | S18: % | U18: 2025 | V18: Previsione | X18: =IF(OR($S18="%",$R18=""),"",$R18*INDEX(Cambi!$J$2:$J$5,MATCH($S18,Cambi!$I$2:$I$5,0))/IF($T18="EUR",1,INDEX(Cambi!$D:$D,MATCH($T18&"|"&$U18,Cambi!$C:$C,0)))) | Y18: Imprese e PA | Z18: Non specificato | AA18: Spesa di sicurezza ICT (perimetro Gartner) | AB18: Non determinabile | AC18: Dedotta. Ipotesi della Commissione costruita su rapporti Gartner globali, non su dati di acquirenti o fornitori UE. | AD18: Modello previsionale o econometrico | AE18: Ipotesi di lavoro della valutazione d'impatto basata su previsioni Gartner 2012-2020 della spesa di sicurezza ICT in rapporto alla spesa ICT e al fatturato, aggiustabile di più o meno 3 punti per settore, applicata al fatturato dei settori NIS. | AF18: reaching about 11.4% of the ICT spending and 0.65% of the total turnover in three to four years | AG18: B | AH18: Pubblico | AI18: Sì | AJ18: Letto da estratto indicizzato della pagina. Anno 2025 dedotto e approssimativo. | AK18: 08/10/2026
A19: 18 | B19: EC-IANIS2-2020 | C19: EU27 | D19: Unione europea (UE27) | E19: UE | F19: Commissione europea | G19: Istituzione UE | H19: SWD(2020) 345 final, Impact assessment report revisione direttiva NIS (allegati) | I19: 16/12/2020 | J19: https://www.eerstekamer.nl/bijlage/20210114/swd_2020_345_impact_assessment_7/document3/f=/vlfghch5jfhz.pdf | K19: Gartner, previsioni 2012-2020 sulla quota di spesa di sicurezza ICT e dati settoriali, citate dalla Commissione | L19: Increase of ICT security spending per sector, Air transport | M19: Aumento complessivo previsto della spesa di sicurezza ICT nel trasporto aereo UE per effetto della NIS2. | N19: Spesa o budget delle organizzazioni | O19: Totale aggregato | P19: Settore | Q19: Trasporto aereo | R19: 0.27 | S19: miliardi | T19: EUR | U19: 2025 | V19: Previsione | X19: =IF(OR($S19="%",$R19=""),"",$R19*INDEX(Cambi!$J$2:$J$5,MATCH($S19,Cambi!$I$2:$I$5,0))/IF($T19="EUR",1,INDEX(Cambi!$D:$D,MATCH($T19&"|"&$U19,Cambi!$C:$C,0)))) -> 270 | Y19: Imprese | Z19: Non specificato | AA19: Spesa di sicurezza ICT (perimetro Gartner) | AB19: Non determinabile | AC19: Dedotta. Ipotesi della Commissione costruita su rapporti Gartner globali, non su dati di acquirenti o fornitori UE. | AD19: Modello previsionale o econometrico | AE19: Ipotesi di lavoro della valutazione d'impatto basata su previsioni Gartner 2012-2020 della spesa di sicurezza ICT in rapporto alla spesa ICT e al fatturato, aggiustabile di più o meno 3 punti per settore, applicata al fatturato dei settori NIS. | AF19: Air transport: an increase of EUR 0.27 billion per sector and EUR 1.18 million | AG19: B | AH19: Pubblico | AI19: Sì | AJ19: Letto da estratto indicizzato della pagina. Incremento di spesa, non livello. Verifica finale 08/10/2026, valore confermato sulla fonte. Incremento stimato per il trasporto aereo confermato. | AK19: 08/10/2026
A20: 19 | B20: EC-IANIS2-2020 | C20: EU27 | D20: Unione europea (UE27) | E20: UE | F20: Commissione europea | G20: Istituzione UE | H20: SWD(2020) 345 final, Impact assessment report revisione direttiva NIS (allegati) | I20: 16/12/2020 | J20: https://www.eerstekamer.nl/bijlage/20210114/swd_2020_345_impact_assessment_7/document3/f=/vlfghch5jfhz.pdf | K20: Gartner, previsioni 2012-2020 sulla quota di spesa di sicurezza ICT e dati settoriali, citate dalla Commissione | L20: Total increase of ICT security spending per company, Electricity and gas | M20: Aumento previsto della spesa di sicurezza ICT per impresa del settore elettricità e gas per effetto della NIS2. | N20: Spesa o budget delle organizzazioni | O20: Media per organizzazione | P20: Settore | Q20: Elettricità e gas | R20: 1.94 | S20: milioni | T20: EUR | U20: 2025 | V20: Previsione | X20: =IF(OR($S20="%",$R20=""),"",$R20*INDEX(Cambi!$J$2:$J$5,MATCH($S20,Cambi!$I$2:$I$5,0))/IF($T20="EUR",1,INDEX(Cambi!$D:$D,MATCH($T20&"|"&$U20,Cambi!$C:$C,0)))) -> 1.94 | Y20: Imprese | Z20: Non specificato | AA20: Spesa di sicurezza ICT (perimetro Gartner) | AB20: Non determinabile | AC20: Dedotta. Ipotesi della Commissione costruita su rapporti Gartner globali, non su dati di acquirenti o fornitori UE. | AD20: Modello previsionale o econometrico | AE20: Ipotesi di lavoro della valutazione d'impatto basata su previsioni Gartner 2012-2020 della spesa di sicurezza ICT in rapporto alla spesa ICT e al fatturato, aggiustabile di più o meno 3 punti per settore, applicata al fatturato dei settori NIS. | AF20: Electricity and gas: a total increase of EUR 6 billion per sector and EUR 1.94 million per company. | AG20: B | AH20: Pubblico | AI20: Sì | AJ20: Letto da estratto indicizzato della pagina. Incremento medio per impresa, non livello. | AK20: 08/10/2026
A21: 20 | B21: EC-IANIS2-2020 | C21: EU27 | D21: Unione europea (UE27) | E21: UE | F21: Commissione europea | G21: Istituzione UE | H21: SWD(2020) 345 final, Impact assessment report revisione direttiva NIS (allegati) | I21: 16/12/2020 | J21: https://www.eerstekamer.nl/bijlage/20210114/swd_2020_345_impact_assessment_7/document3/f=/vlfghch5jfhz.pdf | K21: Gartner, previsioni 2012-2020 sulla quota di spesa di sicurezza ICT e dati settoriali, citate dalla Commissione | L21: Total increase of ICT security spending per sector, Electricity and gas | M21: Aumento complessivo previsto della spesa di sicurezza ICT nel settore elettricità e gas UE per effetto della NIS2 in tre o quattro anni. | N21: Spesa o budget delle organizzazioni | O21: Totale aggregato | P21: Settore | Q21: Elettricità e gas | R21: 6 | S21: miliardi | T21: EUR | U21: 2025 | V21: Previsione | X21: =IF(OR($S21="%",$R21=""),"",$R21*INDEX(Cambi!$J$2:$J$5,MATCH($S21,Cambi!$I$2:$I$5,0))/IF($T21="EUR",1,INDEX(Cambi!$D:$D,MATCH($T21&"|"&$U21,Cambi!$C:$C,0)))) -> 6000 | Y21: Imprese | Z21: Non specificato | AA21: Spesa di sicurezza ICT (perimetro Gartner) | AB21: Non determinabile | AC21: Dedotta. Ipotesi della Commissione costruita su rapporti Gartner globali, non su dati di acquirenti o fornitori UE. | AD21: Modello previsionale o econometrico | AE21: Ipotesi di lavoro della valutazione d'impatto basata su previsioni Gartner 2012-2020 della spesa di sicurezza ICT in rapporto alla spesa ICT e al fatturato, aggiustabile di più o meno 3 punti per settore, applicata al fatturato dei settori NIS. | AF21: Electricity and gas: a total increase of EUR 6 billion per sector and EUR 1.94 million per company. | AG21: B | AH21: Pubblico | AI21: Sì | AJ21: Letto da estratto indicizzato della pagina. Incremento di spesa, non livello. Anno 2025 dedotto dall'orizzonte di tre o quattro anni. | AK21: 08/10/2026
A22: 21 | B22: TECHNOPOLIS-DIGCAP-2026 | C22: EU27 | D22: Unione europea (UE27) | E22: UE | F22: Commissione europea (studio di Technopolis Group) | G22: Istituzione UE | H22: Study on the EU's critical digital capacities deployment beyond 2027, Annex 7 Technology Area Report Cybersecurity and digital identity technologies | I22: 22/06/2026 | J22: https://op.europa.eu/o/opportal-service/download-handler?identifier=fa9b11af-6d4a-11f1-ae88-01aa75ed71a1&format=PDF&language=en&productionSystem=cellar | L22: Contribution of DIGITAL and CEF Digital to Cybersecurity by type of action | M22: Quota del contributo UE 2021-2027 all'area cybersecurity destinata a costruzione dell'ecosistema. | N22: Budget pubblico dedicato | O22: Totale aggregato | P22: Segmento di offerta | Q22: Costruzione dell'ecosistema | R22: 851.7 | S22: milioni | T22: EUR | U22: 2027 | V22: Previsione | X22: =IF(OR($S22="%",$R22=""),"",$R22*INDEX(Cambi!$J$2:$J$5,MATCH($S22,Cambi!$I$2:$I$5,0))/IF($T22="EUR",1,INDEX(Cambi!$D:$D,MATCH($T22&"|"&$U22,Cambi!$C:$C,0)))) -> 851.7 | Y22: Imprese e PA | Z22: Non specificato | AA22: Non specificato | AB22: Non determinabile | AC22: Dedotta. Dotazione di bilancio pubblico, non stima di mercato. | AD22: Non dichiarato | AE22: Elaborazione Technopolis su Digital Europe Dashboard e programmi di lavoro di DIGITAL e CEF Digital. Allocazione finale ancora soggetta a variazioni. | AF22: ecosystem building (€851.7 m), technology deployment (€151.1 m), and digital infrastructure (€65.8 m). | AG22: B | AH22: Pubblico | AI22: Sì | AJ22: Letto da estratto indicizzato della pagina. Verifica finale 08/10/2026, valore confermato sulla fonte. Contributo DIGITAL e CEF Digital nel QFP 2021-2027, anno di chiusura 2027. | AK22: 08/10/2026
A23: 22 | B23: TECHNOPOLIS-DIGCAP-2026 | C23: EU27 | D23: Unione europea (UE27) | E23: UE | F23: Commissione europea (studio di Technopolis Group) | G23: Istituzione UE | H23: Study on the EU's critical digital capacities deployment beyond 2027, Annex 7 Technology Area Report Cybersecurity and digital identity technologies | I23: 22/06/2026 | J23: https://op.europa.eu/o/opportal-service/download-handler?identifier=fa9b11af-6d4a-11f1-ae88-01aa75ed71a1&format=PDF&language=en&productionSystem=cellar | L23: Contribution of DIGITAL and CEF Digital to Cybersecurity by type of action | M23: Quota del contributo UE 2021-2027 all'area cybersecurity destinata a diffusione delle tecnologie. | N23: Budget pubblico dedicato | O23: Totale aggregato | P23: Segmento di offerta | Q23: Diffusione delle tecnologie | R23: 151.1 | S23: milioni | T23: EUR | U23: 2027 | V23: Previsione | X23: =IF(OR($S23="%",$R23=""),"",$R23*INDEX(Cambi!$J$2:$J$5,MATCH($S23,Cambi!$I$2:$I$5,0))/IF($T23="EUR",1,INDEX(Cambi!$D:$D,MATCH($T23&"|"&$U23,Cambi!$C:$C,0)))) -> 151.1 | Y23: Imprese e PA | Z23: Non specificato | AA23: Non specificato | AB23: Non determinabile | AC23: Dedotta. Dotazione di bilancio pubblico, non stima di mercato. | AD23: Non dichiarato | AE23: Elaborazione Technopolis su Digital Europe Dashboard e programmi di lavoro di DIGITAL e CEF Digital. Allocazione finale ancora soggetta a variazioni. | AF23: ecosystem building (€851.7 m), technology deployment (€151.1 m), and digital infrastructure (€65.8 m). | AG23: B | AH23: Pubblico | AI23: Sì | AJ23: Letto da estratto indicizzato della pagina. Verifica finale 08/10/2026, valore confermato sulla fonte. Contributo DIGITAL e CEF Digital nel QFP 2021-2027, anno di chiusura 2027. | AK23: 08/10/2026
A24: 23 | B24: TECHNOPOLIS-DIGCAP-2026 | C24: EU27 | D24: Unione europea (UE27) | E24: UE | F24: Commissione europea (studio di Technopolis Group) | G24: Istituzione UE | H24: Study on the EU's critical digital capacities deployment beyond 2027, Annex 7 Technology Area Report Cybersecurity and digital identity technologies | I24: 22/06/2026 | J24: https://op.europa.eu/o/opportal-service/download-handler?identifier=fa9b11af-6d4a-11f1-ae88-01aa75ed71a1&format=PDF&language=en&productionSystem=cellar | L24: Contribution of DIGITAL and CEF Digital to Cybersecurity by type of action | M24: Quota del contributo UE 2021-2027 all'area cybersecurity destinata a infrastruttura digitale. | N24: Budget pubblico dedicato | O24: Totale aggregato | P24: Segmento di offerta | Q24: Infrastruttura digitale | R24: 65.8 | S24: milioni | T24: EUR | U24: 2027 | V24: Previsione | X24: =IF(OR($S24="%",$R24=""),"",$R24*INDEX(Cambi!$J$2:$J$5,MATCH($S24,Cambi!$I$2:$I$5,0))/IF($T24="EUR",1,INDEX(Cambi!$D:$D,MATCH($T24&"|"&$U24,Cambi!$C:$C,0)))) -> 65.8 | Y24: Imprese e PA | Z24: Non specificato | AA24: Non specificato | AB24: Non determinabile | AC24: Dedotta. Dotazione di bilancio pubblico, non stima di mercato. | AD24: Non dichiarato | AE24: Elaborazione Technopolis su Digital Europe Dashboard e programmi di lavoro di DIGITAL e CEF Digital. Allocazione finale ancora soggetta a variazioni. | AF24: ecosystem building (€851.7 m), technology deployment (€151.1 m), and digital infrastructure (€65.8 m). | AG24: B | AH24: Pubblico | AI24: Sì | AJ24: Letto da estratto indicizzato della pagina. | AK24: 08/10/2026
A25: 24 | B25: TECHNOPOLIS-DIGCAP-2026 | C25: EU27 | D25: Unione europea (UE27) | E25: UE | F25: Commissione europea (studio di Technopolis Group) | G25: Istituzione UE | H25: Study on the EU's critical digital capacities deployment beyond 2027, Annex 7 Technology Area Report Cybersecurity and digital identity technologies | I25: 22/06/2026 | J25: https://op.europa.eu/o/opportal-service/download-handler?identifier=fa9b11af-6d4a-11f1-ae88-01aa75ed71a1&format=PDF&language=en&productionSystem=cellar | L25: Contribution of DIGITAL and CEF Digital to the technology area of Cybersecurity (MFF 2021-2027) | M25: Contributo complessivo dei programmi Europa digitale e CEF Digital all'area cybersecurity nel quadro finanziario 2021-2027. | N25: Budget pubblico dedicato | O25: Totale aggregato | P25: Nessuna | Q25: Totale | R25: 1149 | S25: milioni | T25: EUR | U25: 2027 | V25: Previsione | X25: =IF(OR($S25="%",$R25=""),"",$R25*INDEX(Cambi!$J$2:$J$5,MATCH($S25,Cambi!$I$2:$I$5,0))/IF($T25="EUR",1,INDEX(Cambi!$D:$D,MATCH($T25&"|"&$U25,Cambi!$C:$C,0)))) -> 1149 | Y25: Imprese e PA | Z25: Non specificato | AA25: Non specificato | AB25: Non determinabile | AC25: Dedotta. Dotazione di bilancio pubblico, non stima di mercato. | AD25: Non dichiarato | AE25: Elaborazione Technopolis su Digital Europe Dashboard e programmi di lavoro di DIGITAL e CEF Digital. Allocazione finale ancora soggetta a variazioni. | AF25: the contribution of DIGITAL and CEF Digital to the technology area of Cybersecurity totals €1 149 m | AG25: B | AH25: Pubblico | AI25: Sì | AJ25: Letto da estratto indicizzato della pagina. Dotazione pluriennale 2021-2027 registrata sull'anno di chiusura. | AK25: 08/10/2026
A26: 25 | B26: ECA-COMPENDIUM-2020 | C26: EU27 | D26: Unione europea (UE27) | E26: UE | F26: Corte dei conti europea | G26: Istituzione UE | H26: Audit Compendium Cybersecurity of the EU and its Member States | I26: 12/2020 | J26: https://www.eca.europa.eu/sites/cc/Lists/CCDocuments/Compendium_Cybersecurity/CC_Compendium_Cybersecurity_EN.pdf | K26: Commissione europea (stima citata in nota 65) | L26: EU funding for non-military cybersecurity per year 2014-2020 | M26: Finanziamento UE annuo per la cybersecurity non militare nel periodo 2014-2020 secondo la Commissione, inferiore a 200 milioni. | N26: Budget pubblico dedicato | O26: Totale aggregato | P26: Nessuna | Q26: Totale | R26: 200 | S26: milioni | T26: EUR | U26: 2020 | V26: Consuntivo | X26: =IF(OR($S26="%",$R26=""),"",$R26*INDEX(Cambi!$J$2:$J$5,MATCH($S26,Cambi!$I$2:$I$5,0))/IF($T26="EUR",1,INDEX(Cambi!$D:$D,MATCH($T26&"|"&$U26,Cambi!$C:$C,0)))) -> 200 | Y26: PA | Z26: Non specificato | AA26: Spesa pubblica in cybersecurity | AB26: Non determinabile | AC26: Dedotta. La Corte riprende una stima della Commissione senza descriverne la costruzione. | AD26: Ripreso da altra fonte | AE26: Non dichiarata | AF26: In total, EU funding for non-military cybersecurity has amounted to less than €200 million per year during the 2014-2020 period. | AG26: D | AH26: Pubblico | AI26: No | AJ26: Letto da estratto indicizzato della pagina. Valore soglia (meno di 200 milioni annui), media del periodo 2014-2020. Verifica finale 08/10/2026, valore confermato sulla fonte. Valore annuo massimo confermato nel compendio della Corte dei conti. | AK26: 08/10/2026
A27: 26 | B27: ECA-COMPENDIUM-2020 | C27: EU27 | D27: Unione europea (UE27) | E27: UE | F27: Corte dei conti europea | G27: Istituzione UE | H27: Audit Compendium Cybersecurity of the EU and its Member States | I27: 12/2020 | J27: https://www.eca.europa.eu/sites/cc/Lists/CCDocuments/Compendium_Cybersecurity/CC_Compendium_Cybersecurity_EN.pdf | K27: Commissione europea (stima citata in nota 65) | L27: Horizon 2020 allocation to cybersecurity and cybercrime projects 2014-2020 | M27: Fondi Horizon 2020 assegnati a progetti di cybersecurity e cybercrime nel periodo 2014-2020, inclusi 450 milioni per il partenariato contrattuale. | N27: Budget pubblico dedicato | O27: Totale aggregato | P27: Nessuna | Q27: Totale | R27: 600 | S27: milioni | T27: EUR | U27: 2020 | V27: Consuntivo | X27: =IF(OR($S27="%",$R27=""),"",$R27*INDEX(Cambi!$J$2:$J$5,MATCH($S27,Cambi!$I$2:$I$5,0))/IF($T27="EUR",1,INDEX(Cambi!$D:$D,MATCH($T27&"|"&$U27,Cambi!$C:$C,0)))) -> 600 | Y27: PA | Z27: Non specificato | AA27: Spesa pubblica in cybersecurity | AB27: Non determinabile | AC27: Dedotta. La Corte riprende una stima della Commissione senza descriverne la costruzione. | AD27: Ripreso da altra fonte | AE27: Non dichiarata | AF27: The EU's Horizon 2020 research programmes allocated about €600 million to cybersecurity and cybercrime projects for the period 2014-2020. | AG27: D | AH27: Pubblico | AI27: No | AJ27: Letto da estratto indicizzato della pagina. Cumulato 2014-2020 registrato sull'anno di chiusura. Verifica finale 08/10/2026, valore confermato sulla fonte. Stanziamento Horizon 2020 confermato, riferito al periodo 2014-2020. | AK27: 08/10/2026
A28: 27 | B28: ECCC-DEPWP-2025 | C28: EU27 | D28: Unione europea (UE27) | E28: UE | F28: ECCC, Centro europeo di competenza per la cibersicurezza | G28: Istituzione UE | H28: ECCC Digital Europe Cybersecurity Work Programme 2025-2027 (Decisione GB/2025/4) | I28: 03/2025 | J28: https://cybersecurity-centre.europa.eu/document/download/8af166e1-69c5-4ccd-b38f-5a3ffe43ad73_en?filename=DEP%20WP2025-2027_March2025.pdf | L28: Budget for Cybersecurity actions covered by this Work Programme, by year | M28: Bilancio indicativo annuale delle azioni di cybersecurity del programma Europa digitale gestite dall'ECCC, anno 2025. | N28: Budget pubblico dedicato | O28: Totale aggregato | P28: Nessuna | Q28: Totale | R28: 158 | S28: milioni | T28: EUR | U28: 2025 | V28: Previsione | X28: =IF(OR($S28="%",$R28=""),"",$R28*INDEX(Cambi!$J$2:$J$5,MATCH($S28,Cambi!$I$2:$I$5,0))/IF($T28="EUR",1,INDEX(Cambi!$D:$D,MATCH($T28&"|"&$U28,Cambi!$C:$C,0)))) -> 158 | Y28: Imprese e PA | Z28: Non specificato | AA28: Non specificato | AB28: Non determinabile | AC28: Dedotta. Dotazione di bilancio pubblico, non stima di mercato. | AD28: Non dichiarato | AE28: Dotazione di bilancio programmata, nessuna stima statistica. | AF28: TOTAL (in million EUR) 158 118 114 390 | AG28: B | AH28: Pubblico | AI28: Sì | AJ28: Letto da estratto indicizzato della pagina. Valori indicativi soggetti a decisioni del consiglio di amministrazione, ridotti a circa 355 milioni complessivi dall'emendamento successivo. Verifica finale 08/10/2026, valore confermato sulla fonte. Prima colonna della ripartizione annuale 2025-2027 del programma di lavoro. | AK28: 08/10/2026
A29: 28 | B29: ECCC-DEPWP-2025 | C29: EU27 | D29: Unione europea (UE27) | E29: UE | F29: ECCC, Centro europeo di competenza per la cibersicurezza | G29: Istituzione UE | H29: ECCC Digital Europe Cybersecurity Work Programme 2025-2027 (Decisione GB/2025/4) | I29: 03/2025 | J29: https://cybersecurity-centre.europa.eu/document/download/8af166e1-69c5-4ccd-b38f-5a3ffe43ad73_en?filename=DEP%20WP2025-2027_March2025.pdf | L29: Budget for Cybersecurity actions covered by this Work Programme, by year | M29: Bilancio indicativo annuale delle azioni di cybersecurity del programma Europa digitale gestite dall'ECCC, anno 2026. | N29: Budget pubblico dedicato | O29: Totale aggregato | P29: Nessuna | Q29: Totale | R29: 118 | S29: milioni | T29: EUR | U29: 2026 | V29: Previsione | X29: =IF(OR($S29="%",$R29=""),"",$R29*INDEX(Cambi!$J$2:$J$5,MATCH($S29,Cambi!$I$2:$I$5,0))/IF($T29="EUR",1,INDEX(Cambi!$D:$D,MATCH($T29&"|"&$U29,Cambi!$C:$C,0)))) -> 118 | Y29: Imprese e PA | Z29: Non specificato | AA29: Non specificato | AB29: Non determinabile | AC29: Dedotta. Dotazione di bilancio pubblico, non stima di mercato. | AD29: Non dichiarato | AE29: Dotazione di bilancio programmata, nessuna stima statistica. | AF29: TOTAL (in million EUR) 158 118 114 390 | AG29: B | AH29: Pubblico | AI29: Sì | AJ29: Letto da estratto indicizzato della pagina. Valori indicativi soggetti a decisioni del consiglio di amministrazione, ridotti a circa 355 milioni complessivi dall'emendamento successivo. Verifica finale 08/10/2026, valore confermato sulla fonte. Seconda colonna della ripartizione annuale, corrispondente al 2026. | AK29: 08/10/2026
A30: 29 | B30: ECCC-DEPWP-2025 | C30: EU27 | D30: Unione europea (UE27) | E30: UE | F30: ECCC, Centro europeo di competenza per la cibersicurezza | G30: Istituzione UE | H30: ECCC Digital Europe Cybersecurity Work Programme 2025-2027 (Decisione GB/2025/4) | I30: 03/2025 | J30: https://cybersecurity-centre.europa.eu/document/download/8af166e1-69c5-4ccd-b38f-5a3ffe43ad73_en?filename=DEP%20WP2025-2027_March2025.pdf | L30: Budget for Cybersecurity actions covered by this Work Programme, 2025-2027 | M30: Bilancio complessivo delle azioni di cybersecurity del programma Europa digitale gestite dall'ECCC nel triennio 2025-2027. | N30: Budget pubblico dedicato | O30: Totale aggregato | P30: Nessuna | Q30: Totale | R30: 390 | S30: milioni | T30: EUR | U30: 2027 | V30: Previsione | X30: =IF(OR($S30="%",$R30=""),"",$R30*INDEX(Cambi!$J$2:$J$5,MATCH($S30,Cambi!$I$2:$I$5,0))/IF($T30="EUR",1,INDEX(Cambi!$D:$D,MATCH($T30&"|"&$U30,Cambi!$C:$C,0)))) -> 390 | Y30: Imprese e PA | Z30: Non specificato | AA30: Non specificato | AB30: Non determinabile | AC30: Dedotta. Dotazione di bilancio pubblico, non stima di mercato. | AD30: Non dichiarato | AE30: Dotazione di bilancio programmata, nessuna stima statistica. | AF30: The budget for Cybersecurity actions covered by this Work Programme is of approximatively EUR 390 million30, distributed across 3 years from 2025 to 2027. | AG30: B | AH30: Pubblico | AI30: Sì | AJ30: Letto da estratto indicizzato della pagina. Totale triennale registrato sull'anno di chiusura. Comprende 42 milioni riportati dal 2022. Verifica finale 08/10/2026, valore confermato sulla fonte. Valore cumulato sul triennio 2025-2027 registrato con anno finale 2027. | AK30: 08/10/2026
A31: 30 | B31: ECCC-DEPWP-2025 | C31: EU27 | D31: Unione europea (UE27) | E31: UE | F31: ECCC, Centro europeo di competenza per la cibersicurezza | G31: Istituzione UE | H31: ECCC Digital Europe Cybersecurity Work Programme 2025-2027 (Decisione GB/2025/4) | I31: 03/2025 | J31: https://cybersecurity-centre.europa.eu/document/download/8af166e1-69c5-4ccd-b38f-5a3ffe43ad73_en?filename=DEP%20WP2025-2027_March2025.pdf | L31: Budget for Cybersecurity actions covered by this Work Programme, by year | M31: Bilancio indicativo annuale delle azioni di cybersecurity del programma Europa digitale gestite dall'ECCC, anno 2027. | N31: Budget pubblico dedicato | O31: Totale aggregato | P31: Nessuna | Q31: Totale | R31: 114 | S31: milioni | T31: EUR | U31: 2027 | V31: Previsione | X31: =IF(OR($S31="%",$R31=""),"",$R31*INDEX(Cambi!$J$2:$J$5,MATCH($S31,Cambi!$I$2:$I$5,0))/IF($T31="EUR",1,INDEX(Cambi!$D:$D,MATCH($T31&"|"&$U31,Cambi!$C:$C,0)))) -> 114 | Y31: Imprese e PA | Z31: Non specificato | AA31: Non specificato | AB31: Non determinabile | AC31: Dedotta. Dotazione di bilancio pubblico, non stima di mercato. | AD31: Non dichiarato | AE31: Dotazione di bilancio programmata, nessuna stima statistica. | AF31: TOTAL (in million EUR) 158 118 114 390 | AG31: B | AH31: Pubblico | AI31: Sì | AJ31: Letto da estratto indicizzato della pagina. Valori indicativi soggetti a decisioni del consiglio di amministrazione, ridotti a circa 355 milioni complessivi dall'emendamento successivo. | AK31: 08/10/2026
A32: 31 | B32: ECCC-DEPWPAM2-2025 | C32: EU27 | D32: Unione europea (UE27) | E32: UE | F32: ECCC, Centro europeo di competenza per la cibersicurezza | G32: Istituzione UE | H32: ECCC Digital Europe Cybersecurity Work Programme 2025-2027, emendamento 2 (testo consolidato) | I32: 2025 | J32: https://cybersecurity-centre.europa.eu/document/download/a35f7be2-4464-43d3-a40f-6ec942036f48_en?filename=Amendment2cleanDEPcybersecurityWP2025-2027.pdf | L32: Budget for Cybersecurity actions covered by this Work Programme (amended) | M32: Bilancio rivisto delle azioni di cybersecurity ECCC 2025-2027 dopo la riallocazione di 35 milioni alle AI Gigafactories. | N32: Budget pubblico dedicato | O32: Totale aggregato | P32: Nessuna | Q32: Totale | R32: 355 | S32: milioni | T32: EUR | U32: 2027 | V32: Previsione | X32: =IF(OR($S32="%",$R32=""),"",$R32*INDEX(Cambi!$J$2:$J$5,MATCH($S32,Cambi!$I$2:$I$5,0))/IF($T32="EUR",1,INDEX(Cambi!$D:$D,MATCH($T32&"|"&$U32,Cambi!$C:$C,0)))) -> 355 | Y32: Imprese e PA | Z32: Non specificato | AA32: Non specificato | AB32: Non determinabile | AC32: Dedotta. Dotazione di bilancio pubblico, non stima di mercato. | AD32: Non dichiarato | AE32: Dotazione di bilancio programmata, nessuna stima statistica. | AF32: The budget for Cybersecurity actions covered by this Work Programme is of approximatively EUR 355 million31, distributed across 3 years from 2025 to 2027. | AG32: B | AH32: Pubblico | AI32: Sì | AJ32: Letto da estratto indicizzato della pagina. Totale triennale registrato sull'anno di chiusura. | AK32: 08/10/2026
